Workbook

Sheet Instructions
B2: Screen & Classify — Working Template
B3: Check scientific accuracy & currency; sort by crop, topic and content type
B5: Purpose
B6: • This is the working template for the Screen & Classify step: checking each inventoried item's scientific accuracy and currency, then sorting/classifying it by crop, topic and content type.
B7: • It follows on from the Content Inventory template — every item sourced there gets screened here before it is certified for the Kenya Advisory Knowledge Hub.
B9: How to Use This Workbook
B10: • Each group has its own tab: Crop, Livestock, Fisheries, Soil, and Pest & Disease.
B11: • One row = one content item (one source publication/brochure/guide).
B12: • The first data row on each tab is a worked EXAMPLE (greyed out) — reference only, do not edit. The Livestock tab's example is drawn from a real KALRO publication; see the 'Camel Calf Example' tab for its full section-level breakdown.
B13: • Gold-shaded cells are yours to complete. The ID column auto-numbers itself.
B14: • Use the filter arrows on the header row to sort or filter by Value Chain/Commodity, Advisory Domain/Topic, or Content Type.
B16: Screening Checks
... B22: Field Definitions
B23: Content Title | C23: Title of the source publication/brochure/guide.
B24: Publication ID / Source Link | C24: Unique publication ID and/or URL where the source can be found.
B25: Institution & Author(s) | C25: Originating institution and named author(s).
B26: Publish Date | C26: Date the source was published.
B27: Value Chain / Commodity | C27: Crop, livestock species, fish species or theme this item addresses.
B28: Advisory Domain / Topic | C28: The specific advisory topics covered (e.g. calving management, tick control).
B29: Content Type | C29: Production guide, protocol/SOP, factsheet, advisory bulletin, brochure, training manual, poster/infographic, video.
B30: Format | C30: The medium the content exists in (PDF, text, video, etc.).
B31: Production System | C31: Farming/production system the content applies to (e.g. pastoral, smallholder mixed farming).
B32: Target Users | C32: Who the advisory is written for (farmers, extension officers, CAHWs, etc.).
B33: Country / AEZ | C33: Geographic and agro-ecological applicability.
B34: Last Reviewed (Currency Check) | C34: Date the content was last checked for scientific currency.
... B40: Screening Notes / Escalation Guidance | C40: Reviewer notes, open questions, and who to escalate high-risk items to.
B42: Legend
B43: Fill this in | C43: Gold-shaded cells — enter your screening data here.
B44: Example row | C44: Worked example — reference only, do not edit.

Sheet CROP
B1: ID | C1: Content Title | D1: Publication ID / Source Link | E1: Institution & Author(s) | F1: Publish Date | G1: Value Chain / Commodity | H1: Advisory Domain / Topic | I1: Content Type | J1: Format | K1: Production System | L1: Target Users | M1: Country / AEZ | N1: Last Reviewed (Currency Check) | O1: Currency Status | P1: Scientific Accuracy Check | Q1: Validation Status | R1: Risk Level | S1: Quality Flag | T1: Screening Notes / Escalation Guidance
B2: GRNGRM1 | C2: COMMUNITY SEED BULKING: A model to improve and increase amount of good quality seed to farming communities | D2: https://navcdp.kalro.org/kalroknowledgebank/factsheets/COMMUNITY%20SEED%20BULKING%20Karanja.pdf | E2: KALRO Katumani/Karanja et al. (n.d.) | G2: Green gram | I2: Production Guide | J2: PDF
B3: GRAM-TIMP1 | C3: Inventory of Climate Smart Agriculture Technologies, Innovations and Management Practices for Green Gram Value Chain | D3: https://navcdp.kalro.org/docs/kcsap/Green%20Grams%20TIMP.pdf | E3: KALRO/Wasike V.W., et al. (2022) | G3: Green gram | I3: Production Guide | J3: PDF
B4: Bean1 | C4: Dry bean Climate Smart Agronomic Practices | D4: https://navcdp.kalro.org/kalroknowledgebank/factsheets/Eliezah%20Kamau%20Dry%20beans%20Climate%20smart%20agronomic%20practices%20Fact%20sheet%20June%202021.pdf | E4: KALRO Katumani/Kamau et al. (n.d.) | G4: Bean | I4: Factsheet | J4: PDF
B5: Bean2 | C5: The formal seed system in Kenya | D5: https://navcdp.kalro.org/kalroknowledgebank/factsheets/Formal%20Seed%20System%20In%20Kenya-1%20final%20Karanja.pdf | E5: KALRO Katumani/Karanja et al. (n.d.) | G5: Bean | I5: Factsheet | J5: PDF
B6: Bean3 | C6: Integrated disease management of Powdery mildew disease | D6: https://navcdp.kalro.org/kalroknowledgebank/factsheets/Musitys%20Diseaset%20Powdery%20mildew%20Fact%20sheetl%20June%202021.pdf | E6: KALRO Katumani/Mutisya et al. (2021) | F6: 44348 | G6: Bean | I6: Factsheet | J6: PDF
B7: Bean4 | C7: Integrated disease management of Anthracnose disease | D7: https://navcdp.kalro.org/kalroknowledgebank/factsheets/Mustisya%20Bean%20Diseaset%20Anthracnose%20Fact%20sheet%20June%202021.pdf | E7: KALRO Katumani/Mutisya et al. (2021) | F7: 44348 | G7: Bean | I7: Factsheet | J7: PDF
B8: Bean5 | C8: Integrated disease management of Bacterial blight disease | D8: https://navcdp.kalro.org/kalroknowledgebank/factsheets/Mutisya%20Bean%20Diseaset%20Bacterial%20blight%20IFact%20sheet%20June%202021.pdf | E8: KALRO Katumani/Mutisya et al. (2021) | F8: 44348 | G8: Bean | I8: Factsheet | J8: PDF
B9: Bean6 | C9: Integrated disease management of Common mosaic disease | D9: https://navcdp.kalro.org/kalroknowledgebank/factsheets/Mutisya%20Diseaset%20Common%20mosaic%20virus%20disease%20Fact%20sheetl%20June%202021.pdf | E9: KALRO Katumani/Mutisya et al. (2021) | F9: 44348 | G9: Bean | I9: Factsheet | J9: PDF
B10: Bean7 | C10: Integrated disease management of Rust disease | D10: https://navcdp.kalro.org/kalroknowledgebank/factsheets/Mutisya%20Diseaset%20Rust%20disease%20IDM%20Fact%20sheet%20June%202021.pdf | E10: KALRO Katumani/Mutisya et al. (2021) | F10: 44348 | G10: Bean | I10: Factsheet | J10: PDF
B11: Bean8 | C11: Integrated disease management of Angular leaf spot disease | D11: https://navcdp.kalro.org/kalroknowledgebank/factsheets/Mutisya%20DM-Bean-Diseaset%20Angular%20June%202021.pdf | E11: KALRO Katumani/Mutisya et al. (2021) | F11: 44348 | G11: Bean | I11: Factsheet | J11: PDF
B12: Bean9 | C12: Integrated pest management of aphids in dry bean production | D12: https://navcdp.kalro.org/kalroknowledgebank/factsheets/Mutisya%20pest%20bean%20aphids%20in%20Integrated%20Management%20Fact%20sheet%20June%202021.pdf | E12: KALRO Katumani/Mutisya et al. (2021) | F12: 44348 | G12: Bean | I12: Factsheet | J12: PDF
B13: Bean10 | C13: Integrated pest management of sucking bugs in dry bean production | D13: https://navcdp.kalro.org/kalroknowledgebank/factsheets/Mutisya%20pest%20bean%20sucking%20bugs%20Integrated%20Management%20Fact%20sheetl%20June%202021.pdf | E13: KALRO Katumani/Mutisya et al. (2021) | F13: 44348 | G13: Bean | I13: Factsheet | J13: PDF
B14: Bean11 | C14: Integrated pest management of blister beetle in bean production | D14: https://navcdp.kalro.org/kalroknowledgebank/factsheets/Mutisya%20pest%20blister%20beetle%20IPM%20on%20Bean%20Crop%20Fact%20sheet%20June%202021.pdf | E14: KALRO Katumani/Mutisya et al. (2021) | F14: 44348 | G14: Bean | I14: Factsheet | J14: PDF
B15: Bean12 | C15: Integrated pest management of bollworms in bean production | D15: https://navcdp.kalro.org/kalroknowledgebank/factsheets/Mutisya%20pest%20bollworm%20IPM%20on%20Bean%20Crop%20Fact%20sheet%20June%202021.pdf | E15: KALRO Katumani/Mutisya et al. (2021) | F15: 44348 | G15: Bean | I15: Factsheet | J15: PDF
B16: Bean13 | C16: Integrated pest management of Desert locust in dry bean production | D16: https://navcdp.kalro.org/kalroknowledgebank/factsheets/Mutisya%20pest%20migratory%20desert%20locust%20in%20Integrated%20Management%20Fact%20sheet%20June%202021.pdf | E16: KALRO Katumani/Mutisya et al. (2021) | F16: 44348 | G16: Bean | I16: Factsheet | J16: PDF
B17: Bean14 | C17: Integrated disease management of Red Spider Mite | D17: https://navcdp.kalro.org/kalroknowledgebank/factsheets/Mutisya%20Pest%20Red%20Spider%20mite%20IDM%20Fact%20sheet%20June%202021.pdf | E17: KALRO Katumani/Mutisya et al. (2021) | F17: 44348 | G17: Bean | I17: Factsheet | J17: PDF
... B20: AIV2 | C20: African Indigenous Vegetables (AIVs) Volume II-(Cowpea and Amaranth) | D20: https://navcdp.kalro.org/docs/kcsap/AIV%20Volume%202.pdf | E20: KALRO Katumani/Ndinya et al. (2022) | F20: 44866 | G20: African Indigenous Vegetables (AIVs) | I20: Other | J20: PDF
B21: ="CROP-"&TEXT(19,"000") -> CROP-019
B22: ="CROP-"&TEXT(20,"000") -> CROP-020
B23: AIV3 | C23: African Indigenous Vegetables (AIVs) Volume III-(Nightshade, Jute Mallow and Slendar) | D23: https://navcdp.kalro.org/docs/AIV%20Volume%203.pdf | E23: KALRO Katumani/Ndinya et al. (2022) | F23: 44866 | G23: African Indigenous Vegetables (AIVs) | I23: Other | J23: PDF
B24: Bean-TIMP1 | C24: Dry Bean TIMPs | D24: https://navcdp.kalro.org/docs/kcsap/Final%20Dry-Beans-TIMPs%20for%20upload.pdf | E24: KALRO Katumani/Karanja et al. (2022) | F24: 44835 | G24: Dry Bean | I24: Other | J24: PDF
B25: NRM-TIMP1 | C25: NRM TIMPs | D25: https://navcdp.kalro.org/docs/kcsap/NRM-TIMPs-NEW.pdf | E25: KALRO Katumani/Kamau et al. (2022) | F25: 44835 | G25: NRM | I25: Other | J25: PDF
B26: CROP-EX | C26: Maize (Zea mays) Production Guide - Highland Zones | D26: KALRO-CROP-2024-011 | E26: KALRO Katumani / J. Mwangi | F26: 2024-03-15 | G26: Maize | H26: Production guide; agronomy; variety selection | I26: Production Guide | J26: PDF | K26: Smallholder mixed farming | L26: Smallholder farmers, extension officers | M26: Kenya - Highland zones | N26: 2024-03-15 | O26: Current | P26: Verified | Q26: source_validated | R26: Low | S26: Ready to Certify | T26: Currency check needed against 2026 seed catalogue before certification.
B27: CASSAVA-1 | C27: Technology, Innovations and Management Practices for Cassava | D27: https://navcdp.kalro.org/docs/kcsap/Cassava%20Aug2019-Munga.pdf | E27: Kenya Agricultural and Livestock Research Organization | G27: Cassava | I27: Training Manual | J27: PDF | L27: Farmers
B28: CASSAVA4 | C28: Cassava Training Manual | D28: https://www.kalro.org/navcdp/index.php/information-resoures/publications/training-manuals23 | E28: KALRO-NAVCDP | F28: Not stated | G28: Cassava | H28: Climate-smart cassava production; agronomy; varieties | I28: Training manual | J28: PDF | K28: Smallholder; rainfed | L28: Farmers; extension officers; trainers
B29: CASSAVA-5 | C29: Cassava Climate-Smart Agricultural Technologies Training Manual | D29: https://keep.kalro.org/appfiles/media/vc_files/cassava-8-12-20.pdf | E29: KALRO; climate-smart agriculture programme | F29: Not stated | G29: Cassava | H29: Climate change; FFBS; varieties; clean seed; agronomic practices | I29: Training manual | J29: PDF | K29: Climate-smart; rainfed | L29: Trainers; extension officers; lead farmers; farmers
B30: CASSAVA-6 | C30: Cassava Good Agricultural Practices | D30: https://keep.kalro.org/good-agricultural-practices/Cassava | E30: KALRO Kenya Digital Agriculture Platform | F30: Not stated | G30: Cassava | H30: Varieties; site selection; land preparation; planting; crop management | I30: Digital learning resource | J30: Web | K30: Smallholder; rainfed | L30: Farmers; extension officers
B31: CASSAVA-8 | C31: KALRO New Cassava Varieties | D31: https://www.kalro.org/navcdp/index.php/information-resoures/mobile-apps | E31: KALRO-NAVCDP | F31: Not stated | G31: Cassava | H31: Improved varieties; varietal selection | I31: Mobile learning application | J31: Mobile app | K31: Smallholder; climate-smart | L31: Farmers; extension officers; agro-dealers
B32: CROP-EX | C32: Maize (Zea mays) Production Guide - Highland Zones | D32: KALRO-CROP-2024-011 | E32: KALRO Katumani / J. Mwangi | F32: 2024-03-15 | G32: Maize | H32: Production guide; agronomy; variety selection | I32: Production Guide | J32: PDF | K32: Smallholder mixed farming | L32: Smallholder farmers, extension officers | M32: Kenya - Highland zones | N32: 2024-03-15 | O32: Current | P32: Verified | Q32: source_validated | R32: Low | S32: Ready to Certify | T32: Currency check needed against 2026 seed catalogue before certification.
B33: MAIZE-1 | C33: Farmers’ Extension Handbook Cereals and Pulses | E33: Kenya Agricultural and Livestock Research Organization | F33: 44287 | G33: Maize | I33: Training Manual | J33: PDF | L33: Farmers
B34: MAIZE-2 | C34: Maize smut (Common Smut) | E34: Kiritai S.Kagai K. Ngigi B. Mulaa M. | G34: Maize | H34: Plant Health | I34: Factsheet | J34: PDF | L34: Farmers
B35: MAIZE-3 | C35: Maize Lethal Necrosis Disease on Maize | E35: Gekone M., Otipa M., Kamau R. | G35: Maize | H35: Plant Health | I35: Factsheet | J35: PDF | L35: Farmers
B36: MAIZE-4 | C36: Phosphorus deficiency in Maize | E36: Kiritai S., Kagai K., Mulaa M., Kilalo D., Wendot P., Kiige P., Otipa M. | G36: Maize | H36: Plant Health | I36: Factsheet | J36: PDF | L36: Farmers
B37: MAIZE-5 | C37: Maize Stem Borer | E37: Mulaa M., Oronje M.L., Otipa M., Ringera E.K. | G37: Maize | H37: Plant Health | I37: Factsheet | J37: PDF | L37: Farmers
B38: MAIZE-6 | C38: Maize production training and extension manual | E38: Kenya Agricultural and Livestock Research Organization | F38: 42377 | G38: Maize | I38: Training Manual | J38: PDF | L38: Farmers
B39: MAIZE-7 | C39: Options for Striga management in Kenya | E39: Esilaba A.O. | F39: 38795 | G39: Maize | H39: Plant Health | I39: Factsheet | J39: PDF | L39: Farmers
B40: MAIZE-8 | C40: Harmonized Fertilizer Recommendations For Optimal Maize Production In Kenya | E40: Mangale N., Muriuki A., Kathuku-Gitonga A.N. and Mutegi J.K. | F40: 42644 | G40: Maize | I40: Production Guide | J40: PDF | L40: Farmers
B41: MAIZE-9 | C41: Maize Production Trainng and Extension Manual | D41: Library | E41: Kenya Agricultural and Livestock Research Organization | G41: Maize | I41: Training Manual | J41: PDF | L41: Farmers
B42: MAIZE-10 | C42: Technology, Innovations and Management Practices for Maize Volume II | D42: https://navcdp.kalro.org/docs/timps_2025/MAIZE%20TIMPS%20Volume-1%20for%20Upload.pdf | E42: KALRO/Musila R.N., et al. (2022) | G42: Maize | I42: Training Manual | J42: PDF | L42: Farmers
...

Sheet Sorghum
B1: # | C1: Section Header | D1: Content Summary | E1: Pages | F1: Content Warnings | G1: Content Tags | H1: Status
B2: 1 | C2: Part I - Section 1: Background (1.1 Role in the Kenyan economy; 1.2 Role in food and nutrition security; 1.3 Sorghum as a climate smart innovation; 1.4 Objectives of the training) | D2: Sorghum is a drought and heat tolerant dual-purpose cereal, grown at altitudes of up to 2,500 m a.s.l. and with as little as 300 mm of annual rainfall, though it performs best above 900 mm. In Kenya it occupies an estimated 184,654 ha, mainly on smallholdings in the dryland areas of Western, Eastern and Coast. It serves both food and income: grain for household consumption and, for malting types such as Gadam, a commercial brewing market, alongside a government initiative to blend sorghum flour with other cereals. | E2: SOR-001 | F2: Production and demographic statistics (184,654 ha; over 35% of Kenya's population and more than 26% of livestock in the named regions) are undated and unsourced in the text - verify against current KNBS or MoALD data before reuse in reporting or dashboards. The named commercial brewing partnership creates a market-steering implication; keep it attributed rather than presenting malting sorghum as neutral advice. The flour blending target year (2022) has passed. | G2: background, drought tolerance, dual purpose, Gadam, malting, EABL, flour blending, unsourced statistics | H2: Validated
B3: 2 | C3: Part I - Sections 2–4: Training content, training design and facilitator guidelines | D3: No sorghum subject matter - this section covers how training is designed and delivered rather than the crop itself: module structure and duration, the cascade from a core team of trainers through master trainers to lead farmers, partner roles, venue and demonstration-plot requirements, and evaluation design. | E3: SOR-001 | F3: Section 4.8 is titled 'Facilitator Reference Materials' in the table of contents but 'Participants' Reference Materials' in the body. The reference list is generic (manuals, pamphlets, factsheets) and names no specific publications, so it cannot be reconciled against an asset register as it stands. | G3: training design, 13 modules, ToT cascade, delivery system, partners, evaluation, TOC mismatch | H3: Validated
B4: 3 | C4: Module 1: Climate Change and Climate Smart Agriculture | D4: Climate change reaches sorghum through altered rainfall and rising temperature, and the crop's own drought and heat tolerance is what makes it a climate-smart choice in the first place. Terminology is distinguished carefully - weather from climate, variability from change, adaptation from coping - before projected rainfall and temperature scenarios are matched to specific adaptation measures for the crop. | E4: SOR-001 | F4: Low technical risk. Climate projections presented in 2020 should not be reused as current scenarios. References the 2019 KCEP-CRAL Climate Smart Agriculture Extension Manual, which is a separate asset to catalogue. | G4: climate change, CSA, adaptation, climate projections, triple wins | H4: Validated
B5: 4 | C5: Module 2: Farmer Field and Business School (FFBS) Approach in Sorghum Production | D5: No sorghum subject matter beyond the curriculum framing - this section covers the Farmer Field and Business School method: Agro-Ecosystem Analysis, participatory technology development plots, season-long sessions, field days and graduation, plus facilitation and group leadership skills. | E5: SOR-001 | F5: Non-technical methodology. Module learning outcomes contain a copy error: outcome text refers to identifying climate risks and hazards in sorghum value chain. Minor but confirms cross-value-chain template reuse; check the whole module for other substitutions before ingestion. | G5: FFBS, curriculum matrix, PTD, facilitation, leadership. | H5: Validated
B6: 5 | C6: Module 3: Sorghum Production Niches and Climatic Requirements | D6: Sorghum occupies three broad production niches in Kenya: dry lowlands, dry cold highlands, and semi-humid to humid areas. Suitability within each depends on altitude, soil type, pH and general fertility. County-level agro-ecological zones are reviewed against average yields, typical land sizes and the production constraints particular to each, using suitability maps to match crop to place. | E6: SOR-001 | F6: Stated module duration is inconsistent: section 3.5 says 4 hours while the module summary totals 4 hours 30 minutes. Handouts cite sorghum production guides dated 2017 and 2019 and leaflets from 2017 - all now well aged. | G6: production niches, AEZ, altitude, soils, suitability maps, county yields, duration inconsistency | H6: Validated
B7: 6 | C7: Module 4: Sorghum Variety Selection | D7: Sorghum varieties are chosen by end use as much as by adaptation. The improved varieties are grouped as malting types for brewing, types for human and animal consumption, forage types, and sweet sorghum, each matched to dry lowland, dry cold highland, or semi-humid and humid production areas. Field identification of varieties in an established plot is part of the selection skill. | E7: SOR-001 | F7: Variety recommendations rest on 2017 guides and leaflets and a 2019 extension manual. Variety releases and withdrawals since 2020 are not reflected - verify every named variety against the current KEPHIS National Variety List before farmer-facing release. This is the highest-value module for an advisory tool and therefore the one where staleness does most damage. | G7: variety selection, malting, forage, sweet sorghum, KEPHIS, staleness risk | H7: Validated
B8: 7 | C8: Module 5: Sorghum Seed Systems | D8: Sorghum seed reaches farmers through both formal and informal systems. Quality seed is defined against legal standards, with a certification process, post-certification enforcement, and import and export requirements. Seed multiplication follows set standards, and community seed bulking offers a route where formal supply is weak. Seed requirements can be calculated at county, ward or group level to plan supply. | E8: SOR-001 | F8: Contains legal and regulatory content citing the Seeds and Plant Varieties Act (Cap 326) - statutory references must be checked for amendment before reuse, and regulatory guidance should not be delivered to farmers through an AI channel without a current legal review. | G8: seed systems, certification, Seeds and Plant Varieties Act Cap 326, community seed bulking, regulatory, legal review | H8: Validated
B9: 8 | C9: Module 6: Climate Smart Agronomic Practices for Sorghum | D9: Climate-smart sorghum agronomy begins with enterprise selection and land preparation, then planting at defined seed rates and plant densities, thinning, weed control and rogueing. Cropping system, inter-row and intra-row spacing determine plant population. Conservation agriculture principles apply, and the crop's response depends on seed, fertiliser and manure applied at the right rate and time. | E9: SOR-001 | F9: Input rates and dosage content - the highest-consequence agronomic material in the manual. The abbreviations list defines DAP as 'Di Ammonium Nitrate', which is incorrect: DAP is di-ammonium phosphate. Correct this before ingestion, as an AI would propagate the error into fertiliser advice. Verify all rates against current KALRO fertiliser recommendations. | G9: agronomy, seed rate, plant density, fertiliser rates, conservation agriculture, DAP error, ESCALATE | H9: Validated
B10: 9 | C10: Module 7: Integrated Soil and Water Management Practices for Sorghum Production | D10: Sorghum is grown largely on soils of low fertility and under moisture stress, so soil and water management carries the yield. Soil and plant tissue sampling with accredited laboratory analysis guides nutrition under the 4R principle. Kenyan soils are identified as deficient in nitrogen, phosphorus, potassium, sulphur, zinc, molybdenum and boron. Integrated soil fertility management combines conservation agriculture, cereal-legume intercropping, rotation, manure, mulching and composting; water harvesting and tillage conserve moisture, alongside reclamation of degraded and problematic soils. | E10: SOR-001 | F10: Identifies specific macro- and micronutrient deficiencies in Kenyan soils (N, P, K, S, Zn, Mo, B) - these are broad claims that should retain attribution. Directs users to accredited laboratories but names none; supply a current accredited-laboratory list if this content is used in an advisory flow. | G10: ISFM, soil sampling, 4R stewardship, nutrient deficiency, water harvesting, soil degradation, accredited labs | H10: Validated
B11: 10 | C11: Module 8: Crop Protection and Health Management for Sorghum | D11: Sorghum's most distinctive constraint is bird damage, reported at over 60% loss even with human scaring and total loss without it. Management combines identification of major pests and diseases, scouting against thresholds, and control of post-harvest weevils, with aflatoxin as a linked grain-safety concern. Harvesting white varieties early at the grain hardening dough stage, then drying, is presented as a way to escape bird damage. Safe pesticide use covers knapsack demonstration, protective gear and calibration. | E11: SOR-001 | F11: HIGHEST-RISK MODULE. Bird damage loss figures (over 60% with human scaring, 100% without) are unattributed - retain source or drop. The only pesticide reference is a 2019 PCPB registered-products list hosted on a third-party commercial domain rather than the PCPB register itself; replace with the current official source before any farmer-facing use. Fall armyworm and locusts are described as new and emerging, which is no longer accurate. The dough-stage early harvest technology is explicitly described as not widely known among extension staff and farmers - flag as advisory-with-caveat, not settled practice. | G11: IPM, IDM, bird damage, fall armyworm, locusts, aflatoxin, PCPB, pesticide safety, ESCALATE | H11: Validated
B12: 11 | C12: Module 9: Sorghum Harvesting and Post-Harvest Management | D12: Sorghum grain quality is set at harvest and preserved or lost in storage. Harvesting and drying maintain quality; threshing by machine reduces both labour and grain contamination compared with manual methods; cleaning and drying follow. Storage depends on moisture: the salt method and a moisture meter are used to test grain moisture before sealing into hermetic bags. | E12: SOR-001 | F12: Mentions storage chemicals in the training materials list without naming products or rates - do not synthesise. Grain quality standards are referenced but not specified; align with current KEBS standards before reuse. The salt and moisture-meter method is practical, low-risk content well suited to repackaging. | G12: harvesting, threshing, drying, grain storage, hermetic bags, moisture content, KEBS, storage chemicals | H12: Validated
B13: 12 | C13: Module 10: Sorghum Value Addition | D13: Sorghum grain can be processed into a wide range of foods, which raises both its nutritional contribution and its market value: ugali, porridge, a milk beverage, pilau, doughnuts, cupcakes, biscuits, cake and chapatti. Products are ranked by pairwise comparison to prioritise which opportunities to pursue, and a market strategy developed for the ranked products. Traditional sorghum dishes are noted as appealing less to youth and children than newer product forms. | E13: SOR-001 | F13: Food preparation content with low technical risk and strong repackaging potential. Notes that traditional sorghum recipes appeal less to youth and children - a consumer-acceptance claim that is unattributed. A home economist is recommended to backstop the practical session. | G13: value addition, recipes, nutrition, pairwise ranking, market strategy, consumer acceptance | H13: Validated
... B37: 3 | C37: Seed law framework - partially resolves the Module 5 legal warning | D37: Variety evaluation and release in Kenya is governed by the Seeds and Plant Varieties Act Cap 326 in its 2012 form, together with the Seeds and Plant Varieties (Variety Evaluation and Release) Regulations 2016. Plant breeders' rights are a separate intellectual property right granted by the state over a new variety. KEPHIS notes further regulations under review or development, covering vegetatively propagated seeds (2023), plant breeders' rights (2022) and forest tree seeds (2021). | E37: SOR-005 | F37: PARTIALLY RESOLVES the legal warning recorded against KALRO sorghum Module 5, which cites Cap 326 without stating which version. The operative instruments are the 2012 Act and the 2016 Regulations, not the original enactment. But 'under review or development' means the position is live, so this is not a settled answer - confirm against Kenya Law before any regulatory content reaches farmers. Regulatory guidance should not be delivered through an AI channel without current legal review. | G37: Cap 326, 2012 Act, 2016 Regulations, plant breeders rights, regulations under review, partially resolves Module 5, Kenya Law, legal review required | H37: Validated

Sheet Potato
B1: # | C1: Section Header | D1: Content Summary | E1: Pages | F1: Content Warnings | G1: Content Tags | H1: Status
B2: 1 | C2: Potato Variety: Shangi | D2: Shangi is a 1 m tall semi-erect potato plant with purple flowers, broad leaves, with oval shaped medium to large tubers, with cream white skin, deep pink eyes and cream yellow flesh with a characteristically short dormancy. Suitable altitude is 1400 to 3000 m a.s.l., sufficient and well distributed rainfall or supplement moisture by irrigation, optimal temperature of 15 to 20 °C. Suitable soils of sandy loams preferably but also silty loams and clay loams. This variety is susceptible to late blight and all potato viruses. | E2: ="CROP-"&TEXT(7,"000") -> CROP-007 | F2: Susceptible to late blight and all potato viruses, Short dormancy, Deep eyes cause high wastage during peeling, Poor color of processed products | G2: potato, Shangi, early maturing, susceptible to blight, short dormancy | H2: Validated
B3: 2 | C3: Potato Variety: Kenya Mpya | D3: Kenya Mpya is a high yielding, tolerant to late blight and early maturing variety. It has strong plants which are semi-erect, 1 m high plant with white flowers. The tubers are oval/round shaped, cream white skin, large tubers with shallow pink eyes and cream yellow flesh. It has medium tuber dormancy period, very tolerant to late blight and potato viruses and easily deteriorates when exposed to light during storage. It is suitable for fresh chips and table consumption. | E3: ="CROP-"&TEXT(7,"000") -> CROP-007 | F3: Easily deteriorates when exposed to light during storage, Not suitable for processing | G3: potato, Kenya Mpya, early maturing, late blight tolerant, high yielding | H3: Validated
B4: 3 | C4: Potato variety: Unica | D4: Unica is a medium tall, strong and semi-erect plant with dark green leaves. Unica has purple flowers and has oblong shaped tubers, white shallow eyes, deep red skin and cream white flesh. Unica is drought and heat tolerant, moderately tolerant to late blight, resistant to potato viruses and high yielding >45 t/ha. Unica does well in altitudes below 1500 m a.s.l. to 3000 m a.s.l., well-draining soils preferably silty loams, sandy or clay loams. This variety is drought and heat tolerant and suitable for chipping and table consumption. | E4: ="CROP-"&TEXT(7,"000") -> CROP-007 | F4: Long dormancy requires dormancy breaking technology, Rapid tuber expansion results in large distribution of ware sized tubers even in seed crops | G4: potato, Unica, drought tolerant, heat tolerant, chipping variety | H4: Validated
B5: 4 | C5: Potato variety: Kenya Karibu | D5: Kenya Karibu is a tall, erect plant with strong stems and dark green narrow pointed leaves. The variety yields 35 to 40 t/ha, deep red smooth skin with deep red eyes, and round shaped. Kenya Karibu has medium dormancy period of 3 to 4 months. It is good for table consumption. The variety is not drought tolerant and is tolerant to late blight. It produces very long stolons hence requiring careful use of machinery to avoid damaging newly forming tubers and also needs more earthing up. | E5: ="CROP-"&TEXT(7,"000") -> CROP-007 | F5: Not drought tolerant, Deep eyes cause wastage, Produces very long stolons requiring careful machinery use, Needs more earthing up | G5: potato, Kenya Karibu, late blight tolerant, medium dormancy, table consumption | H5: Validated
B6: 5 | C6: Potato variety: Dutch Robijn | D6: Dutch Robijn is an erect medium tall variety (about 0.7 m in height) with strong stems and dark green medium sized leaves. It flowers scarcely and the flowers are white with a light pink hue. The tubers of this variety are pale red with characteristic rough skin, round in shape (commonly referred to as 'golofu' as the round shape resembles the golf ball). It requires optimal rainfall or supplemental irrigation in case of drought, silty loams, sand clay loam or clay loams. This variety is not drought tolerant and yields are up to 30 t/ha. This variety is susceptible to late blight and potato viruses. | E6: ="CROP-"&TEXT(7,"000") -> CROP-007 | F6: Not drought tolerant, Susceptible to late blight and potato viruses, Limited market outside Bomet County, Processors cite poor quality | G6: potato, Dutch Robijn, crisps processing, susceptible to blight, rough skin | H6: Validated
B7: 6 | C7: Potato variety: Kenya Sherekea | D7: Sherekea is a semi-erect tall variety (slightly below 1 m) with strong stems and pale green, medium sized leaves. It flowers profusely and the flowers are light purple. Sherekea does well in altitudes from 1500 to 2800 m a.s.l.; does well in fertile, well-draining soils with pH of 5.8 to 6.5; sufficient soil moisture; suitable temperature range of 15 to 24 °C. Its tubers are round in shape, smooth red skin with deep red eyes. This variety is tolerant to late blight and PVX. | E7: ="CROP-"&TEXT(7,"000") -> CROP-007 | F7: Long dormancy requires sprouting technology, Deep eyes | G7: potato, Kenya Sherekea, late blight tolerant, PVX tolerant, long dormancy | H7: Validated
B8: 7 | C8: Potato variety: Asante | D8: Asante is an erect tall variety (slightly below 1 m) with strong stems and light green broad leaves. It flowers moderately and the flowers are pink; a high yielding variety (40-45 t/ha); tolerant to late blight; medium dormancy (2 to 3 months). It does well in altitudes from 1500 to 2800 m a.s.l., with a temperature range of 14 to 24 °C. Good soils are the sandy loams and alluvials with good draining capacity and high fertility, with a pH of 5.8 to 6.5. The variety requires sufficient soil moisture throughout its growing period to give a good yield. Asante is not drought tolerant. Its characteristic features include pale red skin with deep red eyes. It is good for table consumption. | E8: ="CROP-"&TEXT(7,"000") -> CROP-007 | F8: Not drought tolerant, Deep eyes, Long dormancy requires sprouting technology | G8: potato, Asante, high yielding, late blight tolerant, table consumption | H8: Validated
B9: 8 | C9: Potato Variety: Tigoni | D9: It is a high yielding variety (35 to 40 t/ha) and tolerant to late blight. It has a medium dormancy period. The variety is suitable for fresh chips, crisps and table consumption. Tigoni does well in high altitudes of above 2100 m to 3000 m a.s.l., with optimal temperatures of 12 to 18 °C. Tigoni requires sufficient rainfall or water supply through irrigation in case of drought. It has very poor storage quality because of greening. Its characteristic features include white skin with shallow white eyes, oval shaped and medium eye depth. | E9: ="CROP-"&TEXT(7,"000") -> CROP-007 | F9: Very poor storage because of greening, Prone to greening both in field and storage, Requires high altitude (above 2100 m) | G9: potato, Tigoni, high altitude, late blight tolerant, greening | H9: Validated
B10: 9 | C10: Potato Variety: Lenana | D10: Lenana—a medium tall potato plant with strong semi erect stems and dark green, medium-sized leaves and white flowers. Shallow eyes, drought/heat tolerant, late maturing, high yielding, resistant to late blight, short dormancy period; suitable for fresh chips, french fries and table consumption. This variety does well in altitudes from 1500 to 3000 m a.s.l. It has oval shaped tubers, white skin, cream white flesh and shallow eye. It is also drought tolerant. | E10: ="CROP-"&TEXT(7,"000") -> CROP-007 | F10: Short dormancy poses storage challenges, Sprouts quickly | G10: potato, Lenana, drought tolerant, late maturing, french fries | H10: Validated
B11: 10 | C11: Potato Variety: Konjo | D11: Konjo—a tall potato plant with strong erect stems and dark green broad leaves, white flowers with a tinge of purple, oval shaped tubers with shallow eyes, medium dormancy period (2-3 months), late maturing, high yielding (40 to 45 t/ha), resistant to late blight, PVX and PVY. It is suitable for table consumption, fresh chips and crisps. The variety does well in altitudes 1500 to 3000 m a.s.l. with optimum temperature of 15 to 18 °C and optimum rainfall of 800 mm. | E11: ="CROP-"&TEXT(7,"000") -> CROP-007 | F11: Seed availability limited, Needs awareness creation | G11: potato, Konjo, high yielding, virus resistant, late maturing | H11: Validated
B12: 11 | C12: Potato Variety: Wanjiku | D12: Wanjiku—medium tall potato plant with strong semi erect stems and dark green, medium-sized leaves with pinkish flowers, drought/heat tolerant, early maturing; very high yielding, resistant to late blight, PVX and PVY, suitable for fresh chips and table consumption. It has short dormancy, oval shaped tubers which have pale white skin with medium deep pink eyes and dormancy period of 1 to 2 months. This variety does well in 1500 to 3000 m a.s.l. altitude, sufficient moisture, well-draining soils and temperatures of 15 to 18 °C. | E12: ="CROP-"&TEXT(7,"000") -> CROP-007 | F12: Seed availability limited, Short dormancy, Needs awareness creation | G12: potato, Wanjiku, drought tolerant, early maturing, virus resistant | H12: Validated
B13: 12 | C13: Potato Variety Nyota | D13: Nyota—cream white skin with pale pink eyes, oval shaped; drought/heat tolerant early maturing; high yielding, susceptible to late blight, short dormancy period; suitable for fresh chips, crisps and table consumption, medium eye depth, poor storage. | E13: ="CROP-"&TEXT(7,"000") -> CROP-007 | F13: Susceptible to late blight, Short dormancy, Poor storage, Seed availability limited | G13: potato, Nyota, drought tolerant, early maturing, susceptible to blight | H13: Validated
... B29: 28 | C29: Positive Seed selection Potato | D29: Positive seed selection is the selection of healthy-looking plants exhibiting vigorous growth to be used as the source of seed potatoes for the next season. By doing so, the number of sick plants in the next crop is reduced significantly. | E29: ="CROP-"&TEXT(7,"000") -> CROP-007 | F29: Big challenge between information availability and accessibility, Non-exposure of end-user, Women might not be aware due to illiteracy | G29: potato, positive seed selection, seed quality, disease management, healthy plants | H29: Validated
B30: 29 | C30: Satellite seed potato bulking Potato | D30: This is a system aimed at promoting and decentralizing seed potato production through organized and registered Seed CIGs. The CIGs are trained on seed potato production guidelines, licensed to use the KALRO license for two seasons to produce certified seed potato, contribute land, labor and security to the project and meet all the KEPHIS inspection and certification costs, while the KALRO may contribute the initial stocks of basic seed potato. The certified seed potato produced is sold directly to seed potato growers who multiply further before selling to ware potato producers. | E30: ="CROP-"&TEXT(7,"000") -> CROP-007 | G30: potato, satellite bulking, CIGs, certified seed, KEPHIS | H30: Validated
B31: 30 | C31: Quality Declared Seed Potato | D31: Quality Declared Seed (QDS) is seed in a quality control system, introduced by FAO, whereby 10% of the seed fields and lots are checked by an autonomous quality control agency and the remainder by the seed production organization. This is seed which is not processed through a formal seed system, but in which quality is assured through the reputational identity of the original source of initial stock. | E31: ="CROP-"&TEXT(7,"000") -> CROP-007 | F31: Non-exposure of end-user, Acceptability by national regulatory organization, VMGs have limited access | G31: potato, QDS, quality declared seed, seed system, FAO | H31: Validated
B32: 31 | C32: Sprouting technologies Potato | D32: Sprouting techniques refer to any form of manipulation or treatment done to seed potato tubers to induce sprouting, a process that marks the end of dormancy stage. Sprouting techniques may be physical or chemical treatments, with the former being preferred. Physical sprouting techniques include normal storage of tubers in diffused light store (DLS) hence allowing normal conditions to bring about the sprouting naturally. Chemical sprouting techniques include the use of synthetic products containing hormones that trigger inhibition of dormancy stage but promotion of vegetative growth stage. | E32: ="CROP-"&TEXT(7,"000") -> CROP-007 | F32: Non-exposure of end-user, Acceptability by national regulatory organization, Women might not be aware due to illiteracy | G32: potato, sprouting, dormancy, DLS, chemical treatment | H32: Validated
B33: 32 | C33: Cut seed potato tubers Potato | D33: Cut seed potato technique refers to a process of cutting a whole seed potato tuber into two or more pieces in a bid to increase quantity of planting materials for potato farmers. The seed potatoes are cut using a sharp knife that is sterilized after every cut in order to prevent transmission of diseases from tuber to tuber. The cut tubers are dipped in wood ash then allowed to cure for a period of 7 to 15 days. When the cut pieces have cured, pieces with at least one sprout are sorted and planted. This technique applies to certified seed potato shortage where the tubers are above 55 mm in diameter. Consideration is made so that the cut made does not injure or damage a sprout, while ensuring that every cut piece has a sprout. | E33: ="CROP-"&TEXT(7,"000") -> CROP-007 | F33: Non-exposure of end-user, Acceptability by national regulatory organization, Risk of disease transmission if knife not sterilized | G33: potato, cut seed, tuber cutting, disease prevention, wood ash | H33: Validated
B34: 33 | C34: True potato seed (TPS) Potato | D34: True potato seed (TPS)/hybrid is the actual botanical seed produced by sexual reproduction and is formed inside the fruits/berries of potato, resembling tomatoes. True potato seed is occasionally formed after the potato has finished flowering. It is considered an alternative source of high quality seed for potato production. While certified seed potatoes take several months to produce, are bulky and deteriorate quickly, TPS/HTPS is lighter to transport, store and handle. | E34: ="CROP-"&TEXT(7,"000") -> CROP-007 | F34: Non-exposure of end-user, Acceptability by national regulatory organization, Women might not be aware due to illiteracy | G34: potato, TPS, true potato seed, hybrid, seed system | H34: Validated
B35: 34 | C35: Food Safety Management System (FSMS) through Hazard Analysis Critical Control Points (HACCP) Plan for Potato Value Chain in Kenya Potato | D35: The Food safety management system (FSMS) through Hazard Analysis and Critical Control Point (HACCP) in potatoes is a system of food safety monitoring and control based on the systematic identification and assessment of various hazards. It is a preventive, rather than a reactive, tool that places the protection of the potato value chain from biological, chemical and physical hazards into the hands of food management systems. This HACCP system is designed to minimize the risk of food safety hazards by identifying the hazards, establishing controls and monitoring these controls. When this HACCP concept is applied to the management of likely adverse health effects resulting from exposure to hazards in the potato value chain, a wholesome and safe potato supply can therefore be maintained improving on trade and health within and outside Kenya’s borders. | E35: ="CROP-"&TEXT(7,"000") -> CROP-007 | F35: Inadequate funds to reach value chain actors, Requires expert team (HACCP specialist, food scientist, microbiologist), Heavy metal accumulations like lead/mercury/cadmium detected | G35: potato, HACCP, food safety, hazard analysis, quality control | H35: Validated
B36: 35 | C36: Global Good Agricultural Practices (GAP) and standards in potato production Potato | D36: It is a systematic process of implementing a standardized production system globally designed to reassure consumers about how food is produced on the farm, pre-farm gate or on-farm standards. It is not about a specific crop production but the process through which production takes place. The four 'pillars' of GAP (economic viability, environmental sustainability, social acceptability and food safety and quality) are included in most private and public sector standards, but the scope which they actually cover varies widely. | E36: ="CROP-"&TEXT(7,"000") -> CROP-007 | F36: Lack/inadequate knowledge on benefits of GAPs, Lack of legislative mechanisms, Perception that GAP is oppressive rather than supportive, Requires a lot of movement on the farm to maintain records | G36: potato, GAP, food safety, quality standards, sustainability | H36: Validated
B37: 36 | C37: Spacing Potato | D37: Spacing is the planting of a specific number of plants per unit area. Spacing is important because it determines plant population and therefore farmers are in a position to project expected yields. Recommended spacing also gives the plant adequate area for root development to absorb nutrients and develop as well as stolon formation, on which tubers are attached. Additionally, proper spacing allows for good air circulation around the plant minimizing the risks of disease infection. Potato requires a spacing of 0.75 m between rows and 0.30 m between plants. | E37: ="CROP-"&TEXT(7,"000") -> CROP-007 | F37: Requires accurate row spacing, Needs thinning for correct plant population, More precision than broadcasting, May need specialized equipment | G37: potato, spacing, plant population, row planting, air circulation | H37: Validated
B38: 37 | C38: Hilling/Earthing up Potato | D38: This is a technique of mounding soil around the base of the potato crop. It can be done manually or mechanically. Earthing up promotes stolonization where tubers are formed and attached. It is also a climate-smart practice which enhances soil moisture conservation as well as protects new tubers from being damaged by potato tuber moth (PTM). | E38: ="CROP-"&TEXT(7,"000") -> CROP-007 | F38: Labour intensive, Women and youth lack access to quality seed potato, Most farmer groups composed of women leaving out men | G38: potato, hilling, earthing up, stolonization, PTM protection | H38: Validated
B39: 38 | C39: Harvesting Potato | D39: This is an agronomic practice of lifting mature potatoes from the ground for purposes of utilization by the end-users. This is done when the potato crop has matured and the vines are completely dry. Alternatively, de-haulming can be done two weeks before harvesting when the crop is physiologically mature; the stage when more than 50% of the potato crop is yellowing, followed by harvesting two weeks later. Harvesting can be manual or mechanized. | E39: ="CROP-"&TEXT(7,"000") -> CROP-007 | F39: Land ownership mainly by men, Women and youth exploited by middlemen, Limited exposure by end-user | G39: potato, harvesting, maturity, de-haulming, mechanization | H39: Validated
B40: 39 | C40: Integrated Manure Management (IMM) Potato | D40: Integrated Manure Management (IMM) is the optimal, site-specific handling of livestock manure from collection, through treatment and storage up to application to crops. Manure is obtained from different animals (poultry, cow, goat, horse) on the farm, but it can also be bought from other farmers or at the market. When managed properly, it provides plant nutrients, builds soil organic matter, and improves soil physical properties all of which are important for soil quality and crop production. | E40: ="CROP-"&TEXT(7,"000") -> CROP-007 | F40: Labour intensive, Can harbor pathogens, May propagate invasive species, Requires proper storage, Contamination of water sources possible | G40: potato, IMM, manure management, soil fertility, organic matter | H40: Validated
B41: 40 | C41: Integrated Soil Fertility Management (ISFM) Potato | D41: A set of soil fertility management practices that include the use of fertilizers, locally available organic inputs and improved seed combined to adapt practices to local conditions. It places emphasis on the importance of using often scarce resources like fertilizer and organic inputs efficiently through techniques such as fertilizer banding (field application of fertilizer directly in area of root-zone to increase the potential for uptake) and micro dosing (applying small quantities of fertilizer with the seed at planting time and a few weeks after emergence). | E41: ="CROP-"&TEXT(7,"000") -> CROP-007 | F41: Technically demanding, May not be responsive in all soils, Requires knowledge of fertilizer banding, VMGs physically disadvantaged | G41: potato, ISFM, fertilizer banding, micro dosing, soil health | H41: Validated
B42: 41 | C42: Rapid soil testing services Potato | D42: This is a dry method for soil testing using simplicity of light—the interaction of electromagnetic radiation with matter to characterize biochemical composition of a soil and/or plant tissue. It requires partners involved (ICRAF, iSDA and SoilCares) to work closely with KALRO and County agricultural officers to sensitize farmers to embrace the testing method. | E42: ="CROP-"&TEXT(7,"000") -> CROP-007 | F42: Requires specialized equipment, Need continuous updating of recommendations, May require sample verification in certified labs, Farmers must trust the information | G42: potato, soil testing, spectroscopy, nutrient analysis, precision agriculture | H42: Validated
... B110: 109 | C110: Policy instruments for the producers of potato Potato | D110: The policy instruments are the means to achieve the National potato policy objectives through stakeholders. Some of the instruments in the National Potato Strategy are provision of extension services, policy implementation, training of staff and farmers on technology transfer by the County governments. Other instruments through KALRO-Tigoni are development and dissemination of suitable technologies, provision of basic seed potato, research on pest and disease management, maintenance and supply of breeder's seed, dissemination of research findings to the MOALD and other stakeholders and capacity building on seed production and marketing. | E110: ="CROP-"&TEXT(7,"000") -> CROP-007 | F110: Disorganization and scattered farmers, Small-scale farming, Inappropriate policy instruments, Women might not have adequate information on CIDP | G110: potato, policy instruments, extension services, technology transfer, implementation | H110: Validated
B111: 110 | C111: Potato Starch | D111: Potato starch is a highly versatile ingredient in the food industry, prized for its neutral taste and odour. This natural thickening agent, stabilizer, and gelling component is gluten-free, making it a popular choice for a wide range of culinary applications. In baking it is used as a binder that enhances the shelf life of baked goods and is a gluten free replacement for wheat flour. In frying, it is used as a coating for fried food to give it a crispy, golden texture. | E111: ="CROP-"&TEXT(25,"000") -> CROP-025 | F111: Requires proper drying to prevent spoilage, Starch yield depends on potato variety and quality | G111: potato starch, gluten-free, thickening agent, baking binder, frying coating | H111: Validated
B112: 111 | C112: Ingredients for Potato Starch Production (Potato) | D112: 6 kg of medium sized potatoes (converted to 1 kg of starch); Clean water | E112: ="CROP-"&TEXT(25,"000") -> CROP-025 | F112: 6 kg potatoes yield only 1 kg starch, Quality of water affects starch quality | G112: potato starch, ingredients, potatoes, water, starch extraction | H112: Validated
B113: 112 | C113: Equipment Required for Potato Starch Production (Potato) | D113: 4 pieces of 5-litre stainless steel containers; Potato peeler; Sieve; Grater; Tray (for drying the starch) | E113: ="CROP-"&TEXT(25,"000") -> CROP-025 | F113: Stainless steel containers required to prevent contamination, Proper drying equipment needed to prevent spoilage | G113: potato starch, equipment, grater, sieve, drying tray | H113: Validated
B114: 113 | C114: Applications of Potato Starch (Potato) | D114: 9. Spread the damp starch evenly onto a tray and allow it to dry until it reaches a powdery consistency. This can be achieved using a solar drier, oven, or by placing the tray in direct sunlight. | E114: ="CROP-"&TEXT(25,"000") -> CROP-025 | F114: May not be suitable for all recipes, Proper storage required to maintain quality | G114: potato starch, food applications, baked goods, soups, dressings | H114: Validated
B115: 114 | C115: Procedure for Potato Starch Production (Potato) | D115: 1. Wash the selected potatoes thoroughly and peel using a peeler 2. Grate the potatoes and place them in a container 3. Add 2 litres of water and let the grated potatoes stand in the water for 10-15 minutes 4. First, thoroughly wash your hands and rinse them with clean water. Next, use your hands to squeeze out the excess starch from the grated potatoes using a sieve. 5. Transfer the material left in the sieve into a separate container, then add 2 litres of water. Allow the mixture to stand for 10-15 minutes. 6. To extract the maximum amount of starch from the grated potato material, use a sieve to squeeze it again. Collect the starch in a separate container. Repeat the process one more time to ensure all the starch has been extracted. 7. Combine all the water that has been strained three times into a single container and let it settle for 60 minutes. After this time, you will notice white sludge accumulating at the bottom of the container. 8. Carefully drain the water, ensuring that the sludge (white solid) is not poured out. What is left behind is wet starch. 9. Spread the damp starch evenly onto a tray and allow it to dry until it reaches a powdery consistency. This can be achieved using a solar drier, oven, or by placing the tray in direct sunlight. 10. Package the dried powder into the specified quantities. | E115: ="CROP-"&TEXT(25,"000") -> CROP-025 | F115: Requires thorough hand washing to prevent contamination, Incomplete drying may lead to mold growth, Starch must settle for full 60 minutes | G115: potato starch, extraction process, grating, settling, drying | H115: Validated
B116: 115 | C116: Applications of Potato Starch (Potato) | D116: Potato starch is a common ingredient in a wide variety of food products, including baked goods like muffins and breads, candies, canned soups, dips, dressings, shredded cheese, spice mixes, and various prepackaged food items. | E116: ="CROP-"&TEXT(25,"000") -> CROP-025 | F116: May not be suitable for all recipes, Proper storage required to maintain quality | G116: potato starch, food applications, baked goods, soups, dressings | H116: Validated
B117: 116 | C117: Potato Crisps | D117: Potato crisps is a fried potato snack that typically consists of 30-35% oil and 2-10% of flavour. It is a preferred snack that is very marketable in urban centres. | E117: ="CROP-"&TEXT(26,"000") -> CROP-026 | F117: Contains 30-35% oil, Not considered nutritious (630-840 kJ, i.e. 150-200 kcal, per 28 g) | G117: potato crisps, fried snack, high oil content, marketable, urban centres | H117: Validated
B118: 117 | C118: Introduction to Potato Crisps (potato) | D118: Ware potatoes are seasonal and occasionally experience periods of overproduction. During these periods, prices plummet and farmers experience losses. Value added products such as potato crisps are some of the products that can be made during the periods of potato glut and sold over extended periods of time since they have long shelf life. Through value addition, farmers may sell some of their produce to crisps processors at favourable prices. The value addition stands to benefit the youth, the vulnerable and marginalized communities, who wish to benefit in one way or another in the potato value chain. | E118: ="CROP-"&TEXT(26,"000") -> CROP-026 | F118: 1 kg potatoes yields only 250-280 g of crisps, Requires investment in equipment (deep fryer, sealer, etc.) | G118: potato crisps, value addition, income generation, potato glut, shelf life | H118: Validated
B119: 118 | C119: Ingredients for Potato Crisps (potato) | D119: 1 kg of potato tubers (makes 250 to 280 g of crisps); Vegetable cooking oil (amount depends on type and size of fryer); Water for washing tubers; Herbs and spices (optional); Salt as desired | E119: ="CROP-"&TEXT(26,"000") -> CROP-026 | F119: High oil consumption required, Only 25-28% yield from raw potatoes | G119: potato crisps, ingredients, potatoes, cooking oil, seasonings | H119: Validated
B120: 119 | C120: Equipment Required for Potato Crisps (potato) | D120: Potato peeler; Potato slicer; Strainer; Hot bath; Waste bucket; Container; Deep fryer; Weighing scale; Packaging material; Sealer | E120: ="CROP-"&TEXT(26,"000") -> CROP-026 | F120: Requires significant equipment investment, Deep fryer needed (thermostat recommended) | G120: potato crisps, equipment, deep fryer, slicer, packaging | H120: Validated
B121: 120 | C121: Procedure for Potato Crisps Production (potato) | D121: 1. Select medium sized potatoes of a similar size and shape. Freshly harvested ones give a higher number of crisps compared to those that had been stored. 2. Peel the selected potatoes (optional) and wash the peeled potatoes thoroughly before slicing them into thin, 3 mm thick slices using a slicer. 3. Wash the cut slices with water, 2 or 3 times to remove starch. 4. To blanch or cook the crisps, slightly immerse them in a hot water bath (75-80 °C) using a strainer for 2-3 minutes. 5. Remove the strainer from the water bath and let the excess water drain for 5-10 minutes. This will also allow the par-cooked slices to cool down. 6. Transfer the par-cooked slices from the blanching strainer to the deep-frying wire mesh basket. 7. Pour vegetable cooking oil into the deep-frying machine and heat the oil to about 170 °C (use the fryer's inbuilt thermostat). 8. Deep fry the potato slices in small batches and constantly check the temperature to ensure that it remains at about 170 °C. 9. If your fryer does not have a thermostat, remove the crisps occasionally during the deep-frying process to allow the oil to heat up. Do this until the crisps are cooked. 10. Remove the frying mesh containing the fried crisps from the oil, and position it in a manner that facilitates the draining of excess oil. 11. Arrange the freshly prepared crisps on a tray, sprinkle with salt and any desired seasonings, and allow them to cool. 12. Place the crisps in airtight packets, weigh and seal. Entry of air into the packet may lead to loss of crispiness, leading to spoilage. | E121: ="CROP-"&TEXT(26,"000") -> CROP-026 | F121: Freshly harvested potatoes give better results, Oil must be at 170 °C, Air entry causes loss of crispiness, Requires constant temperature monitoring | G121: potato crisps, processing procedure, blanching, deep frying, packaging | H121: Validated
B122: 121 | C122: Caution for Potato Crisps Production (potato) | D122: 1. Tubers that are immature, identified by their easily peeling skin when rubbed using your fingers, will result in crisps that are undesirable and dark brown colour. This is caused by the high sugar content found in such tubers. 2. Fried potato crisps are not typically viewed as a nutritious snack option. A single serving of 28 g, which is roughly equivalent to 18 crisps, contains approximately 630 to 840 kJ (150 to 200 kcal), 10 g of fat, 15 g of carbohydrates and 2 g of protein. | E122: ="CROP-"&TEXT(26,"000") -> CROP-026 | F122: Immature potatoes produce dark brown crisps, High calorie and fat content (630-840 kJ, i.e. 150-200 kcal, per 28 g) | G122: potato crisps, caution, immature potatoes, nutrition, dark colour | H122: Validated
...

Sheet Millet
B1: # | C1: Section Header | D1: Content Summary | E1: Pages | F1: Content Warnings | G1: Content Tags | H1: Status
B2: 1 | C2: Finger Millet Variety Maridadi | D2: An early maturing (90–120 days), synchronous in maturity and high yielding variety (1,100–4,900 kg ha⁻¹, depending on environment) that is resistant to blast, Striga and lodging, and tolerant to drought. Its characteristic features include brown grain colour, purple nodal pigmentation, incurved fist-like panicles; it is the most popular improved variety in western Kenya. Optimal environmental conditions: rainfall (600–900 mm annually), altitude (0–1,500 m a.s.l.) and soils (well-draining loams). | E2: ="CROP-"&TEXT(31,"000") -> CROP-031 | F2: Yields vary significantly with environment, Requires specific rainfall conditions, Not adapted to all agro-ecological zones, Seed availability may be limited outside western Kenya, May not perform well in high altitude areas | G2: finger millet, early maturing, drought tolerant, blast resistant, high yielding | H2: Validated
